Workbook

Sheet قطعه 17
B1: ردیف | C1: نام | D1: نام خانوادگی | E1: قطعه | F1: ردیف | G1: شماره | H1: بلوک | I1: ترمیم /تعویض | J1: تعویضی | K1: مرمتی | L1: ارسال به واحد مرمت | M1: سنگ مرمتی آماده | N1: نصب مرمتی شده | O1: ارسال به واحد تعویض | P1: سنگ تعویضی آماده | Q1: تعویضی نصب شده | R1: ملاحظات
B2: 1 | C2: ربابه | D2: خادم اسابقی | E2: 17 | F2: 4 | G2: 56 | I2: ترمیمی | K2: 1 | N2: 1

Sheet قطعه 24
B1: ردیف | C1: نام | D1: نام خانوادگی | E1: قطعه | F1: ردیف | G1: شماره | H1: ترمیم /تعویض | I1: تعویضی | J1: مرمتی | K1: ارسال به واحد مرمت | L1: سنگ مرمتی آماده | M1: نصب مرمتی شده | N1: ارسال به واحد تعویض | O1: سنگ تعویضی آماده | P1: تعویضی نصب شده | Q1: ملاحظات
B2: 1 | C2: ابراهیم | D2: براتعلی | E2: 24 | H2: ترمیمی | J2: 1
B3: 2 | C3: ابراهیم علی | D3: چراغی | E3: 24 | H3: تعویض | I3: 1
B4: 3 | C4: ابوالقاسم | D4: عزیزی | E4: 24 | F4: 43 | G4: 22 | H4: ترمیمی | J4: 1
B5: 4 | C5: احمد | D5: بختیاری | E5: 24 | F5: 68 | G5: 20 | H5: ترمیمی | J5: 1
B6: 5 | C6: احمد | D6: پور احمد | E6: 24 | F6: 61 | G6: 23 | H6: تعویض | I6: 1 | P6: 1
B7: 6 | C7: احمد | D7: حلبحی | E7: 24 | F7: 16 | G7: 10 | H7: تعویض | I7: 1 | N7: 1
B8: 7 | C8: احمد | D8: رحیمی | E8: 24 | F8: 72 | G8: 16 | H8: ترمیمی | J8: 1
B9: 8 | C9: احمد رضا | D9: مبینی | E9: 24 | F9: 62 | G9: 28 | H9: ترمیمی | J9: 1 | M9: 1
B10: 9 | C10: احمد | D10: سبزیکاری | E10: 24 | F10: 72 | G10: 14 | H10: ترمیمی | J10: 1
B11: 10 | C11: احمد | D11: سرباز چهره برقی | E11: 24 | F11: 62 | G11: 13 | H11: تعویض | I11: 1 | P11: 1
B12: 11 | C12: احمد | D12: عربی | E12: 24 | F12: 115 | G12: 12 | H12: ترمیمی | J12: 1
B13: 12 | C13: احمد | D13: فتحی | E13: 24 | F13: 61 | G13: 3 | H13: تعویض | I13: 1 | P13: 1
B14: 13 | C14: اروجعلی | D14: عسگری | E14: 24 | F14: 137 | G14: 27 | H14: ترمیمی | J14: 1 | M14: 1
B15: 14 | C15: اسحابعلی | D15: میری سیاهی | E15: 24 | F15: 18 | G15: 29 | H15: ترمیمی | J15: 1
B16: 15 | C16: اسحاق | D16: یوسف زاده | E16: 24 | F16: 24 | G16: 2 | H16: تعویض | I16: 1 | P16: 1
B17: 16 | C17: اسداله | D17: حجری | E17: 24 | H17: تعویض | I17: 1 | N17: 0
B18: 17 | C18: اسرافیل | D18: مختاری | E18: 24 | F18: 63 | G18: 19 | H18: ترمیمی | J18: 1
B19: 18 | C19: اسماعیل | D19: رحیمی | E19: 24 | F19: 38 | G19: 7 | H19: ترمیمی | J19: 1
B20: 19 | C20: اصغر | D20: حاجی نوروزی | E20: 24 | F20: 31 | G20: 21 | H20: ترمیمی | J20: 1
B21: 20 | C21: اصغر | D21: خانی | E21: 24 | F21: 33 | G21: 29 | H21: تعویض | I21: 1 | O21: 1
B22: 21 | C22: اصغر | D22: علیزاده | E22: 24 | F22: 23 | G22: 31 | H22: ترمیمی | J22: 1
B23: 22 | C23: اصغر | D23: کبریان | E23: 24 | F23: 50 | G23: 12 | H23: تعویض | I23: 1
B24: 23 | C24: اکبر | D24: فخفوری | E24: 24 | F24: 16 | G24: 15 | H24: ترمیمی | J24: 1
B25: 24 | C25: الهه | D25: توتونچی | E25: 24 | F25: 28 | G25: 10 | H25: تعویض | I25: 1 | N25: 0
B26: 25 | C26: امیر حسین | D26: داستانپور | E26: 24 | F26: 121 | G26: 29 | H26: تعویض | I26: 1 | O26: 1
B27: 26 | C27: امیر محمد | D27: رضائی نیکو | E27: 24 | H27: ترمیمی | J27: 1
B28: 27 | C28: امیرحسین | D28: برنده | E28: 24 | F28: 36 | G28: 1م | H28: تعویض | I28: 1 | P28: 1
B29: 29 | C29: بهراد | D29: محرم نژاد | E29: 24 | F29: 61 | G29: 40 | H29: تعویض | I29: 1 | P29: 1
B30: 30 | C30: بهرام | D30: فریدونی بهرامی | E30: 24 | F30: 21 | G30: 16 | H30: ترمیمی | J30: 1
B31: 31 | C31: بهزاد | D31: صدفی | E31: 24 | F31: 23 | G31: 8 | H31: ترمیمی | J31: 1
B32: 32 | C32: بهمن | D32: کلامی | E32: 24 | F32: 19 | G32: 29 | H32: ترمیمی | J32: 1
B33: 33 | C33: بیژن | D33: شعبانی | E33: 24 | F33: 48 | G33: 18 | H33: ترمیمی | J33: 1 | M33: 1
B34: 34 | C34: جعفر | D34: سلطانی | E34: 24 | F34: 54 | G34: 19 | H34: ترمیمی | J34: 1
B35: 35 | C35: جلیل | D35: بنده | E35: 24 | F35: 31 | G35: 4 | H35: ترمیمی | J35: 1
B36: 36 | C36: جمشید | D36: دیانت پور | E36: 24 | F36: 60 | G36: 26 | H36: ترمیمی | J36: 1
B37: 37 | C37: جمشید | D37: قلی زاده | E37: 24 | F37: 73 | G37: 26 | H37: ترمیمی | J37: 1
B38: 38 | C38: جواد | D38: جلالوند | E38: 24 | F38: 29 | G38: 1م | H38: تعویض | I38: 1 | P38: 1
B39: 39 | C39: حاج احمد | D39: علی پور | E39: 24 | F39: 103 | G39: 28 | H39: ترمیمی | J39: 1 | M39: 1
B40: 40 | C40: حاج حسن | D40: پورمند | E40: 24 | F40: 126 | G40: 29 | H40: ترمیمی | J40: 1
...

Sheet قطعه 26
B1: ردیف | C1: نام | D1: نام خانوادگی | E1: قطعه | F1: ردیف | G1: شماره | H1: ترمیم /تعویض | I1: تعویضی | J1: مرمتی | K1: ارسال به واحد مرمت | L1: سنگ مرمتی آماده | M1: نصب مرمتی شده | N1: ارسال به واحد تعویض | O1: سنگ تعویضی آماده | P1: تعویضی نصب شده | Q1: توضیحات
B2: 1 | C2: حمید | D2: مهر محمد | E2: 26 | F2: 42 | G2: 1 | H2: ترمیمی | J2: 1
B3: 2 | C3: مصطفی | D3: احسانی | E3: 26 | F3: 82 | G3: 1 | H3: ترمیمی | J3: 1
B4: 3 | C4: احمد | D4: اابوئی مهریزی | E4: 26 | F4: 60 | G4: 2 | H4: ترمیمی | J4: 1 | Q4: سنگ مرمر میباشد
B5: 4 | C5: جواد | D5: یافتیان | E5: 26 | F5: 96 | G5: 3 | H5: ترمیمی | J5: 1
B6: 5 | C6: احمد | D6: موحدی | E6: 26 | F6: 79 | G6: 3 | H6: ترمیمی | J6: 1 | Q6: سنگ کوتاه شود
B7: 6 | C7: محمدجعفر | D7: طباطبائی قمی | E7: 26 | F7: 41 | G7: 3 | H7: ترمیمی | J7: 1 | Q7: سنگ مرمر میباشد
B8: 7 | C8: محمد رضا | D8: دارائی | E8: 26 | F8: 80 | G8: 3 | H8: ترمیمی | J8: 1 | Q8: سنگ مرمر میباشد
B9: 8 | C9: محمدرضا | D9: تعقلی | E9: 26 | F9: 98 | G9: 4 | H9: ترمیمی | J9: 1 | Q9: سنگ مرمر میباشد
B10: 10 | C10: حمید | D10: فدائی تهرانی | E10: 26 | F10: 60 | G10: 5 | H10: ترمیمی | J10: 1 | Q10: سنگ مرمر میباشد
B11: 11 | C11: صفر علی | D11: داودی | E11: 26 | F11: 78 | G11: 6 | H11: ترمیمی | J11: 1
B12: 14 | C12: عادل | D12: سقایی سقولو | E12: 26 | F12: 81 | G12: 7 | H12: ترمیمی | J12: 1 | Q12: سنگ مرمر میباشد
B13: 15 | C13: غلامرضا | D13: رستمی | E13: 26 | F13: 78 | G13: 7 | H13: ترمیمی | J13: 1 | Q13: سنگ مرمر میباشد
B14: 16 | C14: محمدرضا | D14: تارخی | E14: 26 | F14: 83 | G14: 8 | H14: ترمیمی | J14: 1
B15: 17 | C15: حیدر | D15: مرادی | E15: 26 | F15: 86 | G15: 8 | H15: ترمیمی | J15: 1 | M15: 1
B16: 18 | C16: محمدکاظم | D16: کلهر | E16: 26 | F16: 91 | G16: 8 | H16: ترمیمی | J16: 1 | Q16: سنگ مرمر میباشد
B17: 19 | C17: مرتضی | D17: کهتری | E17: 26 | F17: 86 | G17: 9 | H17: ترمیمی | J17: 1 | Q17: سنگ مرمر میباشد
B18: 20 | C18: فاضل | D18: محرمی | E18: 26 | F18: 81 | G18: 9 | H18: ترمیمی | J18: 1 | Q18: سنگ مرمر میباشد
B19: 21 | C19: فرهاد | D19: ادبی فرد | E19: 26 | F19: 59 | G19: 14 | H19: ترمیمی | J19: 1
B20: 22 | C20: محسن | D20: خیاط زاده | E20: 26 | F20: 78 | G20: 14 | H20: ترمیمی | J20: 1
B21: 23 | C21: حیدر علی | D21: رضائی | E21: 26 | F21: 89 | G21: 15 | H21: ترمیمی | J21: 1
B22: 24 | C22: جمال | D22: علینژاد آقبلاغ | E22: 26 | F22: 67 | G22: 17 | H22: ترمیمی | J22: 1
B23: 25 | C23: محمد حسن | D23: طهماسبی آشتیانی | E23: 26 | F23: 30 | G23: 17 | H23: ترمیمی | J23: 1 | M23: 1
B24: 26 | C24: علی(مرهداد) | D24: پورمند | E24: 26 | F24: 57 | G24: 18 | H24: ترمیمی | J24: 1
B25: 27 | C25: ناصر | D25: ملاجعفر | E25: 26 | F25: 90 | G25: 19 | H25: ترمیمی | J25: 1 | Q25: سنگ کوتاه شود
B26: 28 | C26: محمد سعید | D26: ابوالمعالی حسینی | E26: 26 | F26: 90 | G26: 19 | H26: ترمیمی | J26: 1 | M26: 1
B27: 29 | C27: عباس | D27: حسینی | E27: 26 | F27: 87 | G27: 20 | H27: ترمیمی | J27: 1
B28: 30 | C28: سید حسن | D28: دریاباری | E28: 26 | F28: 95 | G28: 21 | H28: ترمیمی | J28: 1
B29: 31 | C29: رضا | D29: قانع آبادی استاد | E29: 26 | F29: 3 | G29: 30 | H29: ترمیمی | J29: 1 | M29: 1
B30: 32 | C30: علیرضا | D30: نوروی زاده | E30: 26 | F30: 44 | G30: 30 | H30: ترمیمی | J30: 1
B31: 33 | C31: حسن | D31: زارع پور چونیانی | E31: 26 | F31: 33 | G31: 30 | H31: ترمیمی | J31: 1
B32: 34 | C32: مرتضی | D32: حیدری | E32: 26 | F32: 5 | G32: 31 | H32: ترمیمی | J32: 1 | Q32: سنگ مرمر میباشد
B33: 35 | C33: مهدی | D33: اکبری | E33: 26 | F33: 32 | G33: 33 | H33: ترمیمی | J33: 1
B34: 36 | C34: غلامرضا | D34: گل دست | E34: 26 | F34: 79 | G34: 33 | H34: ترمیمی | J34: 1 | M34: 1
B35: 37 | C35: مرتضی | D35: زنجانی کرامتی | E35: 26 | F35: 50 | G35: 34 | H35: ترمیمی | J35: 1
B36: 38 | C36: *** | D36: شهید گمنام | E36: 26 | F36: 35 | G36: 34 | H36: ترمیمی | J36: 1
B37: 39 | C37: علی اصغر | D37: پور سلطان | E37: 26 | F37: 63 | G37: 36 | H37: ترمیمی | J37: 1
B38: 40 | C38: ناصر | D38: صالی | E38: 26 | F38: 34 | G38: 38 | H38: ترمیمی | J38: 1
B39: 41 | C39: محمد | D39: قلی بیگیان | E39: 26 | F39: 9 | G39: 38 | H39: ترمیمی | J39: 1 | M39: 1
B40: 42 | C40: محبوب | D40: درزجی دولق | E40: 26 | F40: 2 | G40: 39 | H40: ترمیمی | J40: 1 | M40: 1
...

Sheet قطعه 27
B1: ردیف | C1: نام | D1: نام خانوادگی | E1: قطعه | F1: ردیف | G1: شماره | H1: ترمیم /تعویض | I1: تعویضی | J1: مرمتی | K1: ارسال به واحد مرمت | L1: سنگ مرمتی آماده | M1: نصب مرمتی شده | N1: ارسال به واحد تعویض | O1: سنگ تعویضی آماده | P1: تعویضی نصب شده | Q1: توضیحات
B2: 1 | C2: محمود | D2: صابر درویش | E2: 27 | F2: 123 | H2: ترمیمی | J2: 1
B3: 2 | C3: علی | D3: اقبالی مقدم | E3: 27 | H3: ترمیمی | J3: 1
B4: 3 | C4: محمدرضا | D4: حسینجانی | E4: 27 | H4: ترمیمی | J4: 1
B5: 4 | C5: اسماعیل | D5: قمری | E5: 27 | H5: ترمیمی | J5: 1
B6: 5 | C6: حسین | D6: اسدی | E6: 27 | F6: 47 | G6: 5 | H6: ترمیمی | J6: 1
B7: 6 | C7: علی | D7: باقرپور | E7: 27 | F7: 141 | G7: 2 | H7: ترمیمی | J7: 1
B8: 7 | C8: محمد رضا | D8: عاطفی | E8: 27 | F8: 111 | G8: الف | H8: ترمیمی | J8: 1 | M8: 1
B9: 8 | C9: محمدباقر | D9: عبایی هدش | E9: 27 | H9: ترمیمی | J9: 1
B10: 9 | C10: ناصر | D10: استاد عظیم | E10: 27 | H10: ترمیمی | J10: 1
B11: 10 | C11: رحمان | D11: گرگانی تهرانی | E11: 27 | F11: 86 | G11: 9 | H11: ترمیمی | J11: 1
B12: 11 | C12: کاظم | D12: توکلی | E12: 27 | F12: 41 | G12: 6 | H12: تعویضی | I12: 1 | P12: 1
B13: 12 | C13: محمدهادی | D13: هدایت پور | E13: 27 | H13: ترمیمی | J13: 1
B14: 13 | C14: رضا | D14: مصیحی نیا | E14: 27 | H14: ترمیمی | J14: 1
B15: 14 | C15: داریوش | D15: موسی الرضا | E15: 27 | F15: 6 | G15: 5 | H15: ترمیمی | J15: 1
B16: 15 | C16: یوسف | D16: فعال | E16: 27 | H16: ترمیمی | J16: 1
B17: 16 | C17: قاسم | D17: شریفی | E17: 27 | H17: ترمیمی | J17: 1
B18: 17 | C18: علیرضا | D18: سخائی | E18: 27 | F18: 32 | G18: 4 | H18: ترمیمی | J18: 1
B19: 18 | C19: ایرج | D19: حبیبی | E19: 27 | F19: 55 | G19: 4 | H19: ترمیمی | J19: 1
B20: 19 | C20: علی رضا | D20: طاهرپناه | E20: 27 | F20: 12 | G20: الف | H20: ترمیمی | J20: 1
B21: 20 | C21: امیر | D21: متولی | E21: 27 | F21: 24 | G21: 3 | H21: ترمیمی | J21: 1
B22: 21 | C22: محمد مهدی | D22: کریمی | E22: 27 | H22: ترمیمی | J22: 1
B23: 22 | C23: بهروز | D23: لطیفی | E23: 27 | H23: ترمیمی | J23: 1
B24: 23 | C24: غلامرضا | D24: ایرانی | E24: 27 | H24: ترمیمی | J24: 1
B25: 24 | C25: *** | D25: نوری | E25: 27 | G25: الف | H25: ترمیمی | J25: 1
B26: 25 | C26: مهدی | D26: براتلو | E26: 27 | F26: 24 | G26: الف | H26: ترمیمی | J26: 1
B27: 26 | C27: غلامرضا | D27: حنیفه زاده مرندی | E27: 27 | F27: 62 | G27: ب | H27: ترمیمی | J27: 1
B28: 27 | C28: علی | D28: قنبر | E28: 27 | F28: 56 | G28: ب | H28: ترمیمی | J28: 1
B29: 28 | C29: محمد حسن | D29: میرزائی فراهانی | E29: 27 | H29: ترمیمی | J29: 1
B30: 29 | C30: سیدحسین | D30: مصطفوی | E30: 27 | F30: 20 | G30: ت | H30: ترمیمی | J30: 1
B31: 30 | C31: مهران | D31: عزیزانی | E31: 27 | H31: ترمیمی | J31: 1
B32: 31 | C32: قربانعلی | D32: عابدی | E32: 27 | F32: 41 | G32: ج | H32: ترمیمی | J32: 1
B33: 32 | C33: علی | D33: گیلانی | E33: 27 | G33: ج | H33: ترمیمی | J33: 1
B34: 33 | C34: علی اصغر | D34: قدیانی | E34: 27 | H34: ترمیمی | J34: 1
B35: 34 | C35: حسن | D35: جلودار زاده | E35: 27 | H35: تعویضی | I35: 1 | O35: 1 | Q35: تصویر شهید با هوش مصنوعی احیا و در سنگ جدید حک شود
B36: 35 | C36: حسین | D36: یزدی | E36: 27 | H36: تعویضی | I36: 1 | N36: 1
B37: 36 | C37: حسین | D37: رحیمی | E37: 27 | F37: 12 | G37: 6 | H37: تعویضی | I37: 1 | P37: 1
B38: 37 | C38: شهرام | D38: دربندی | E38: 27 | H38: تعویضی | I38: 1 | N38: 1 | Q38: اول چک شود مرمر به نظر میرسد
B39: 38 | C39: *** | D39: شهید گمنام | E39: 27 | F39: 137 | G39: 1 | H39: تعویضی | I39: 1 | Q39: انجام شد
B40: 39 | C40: محمد | D40: صادقی | E40: 27 | F40: 138 | G40: الف | H40: تعویضی | I40: 1 | P40: 1
...

Sheet قطعه 28
B1: ردیف | C1: نام | D1: نام خانوادگی | E1: قطعه | F1: ردیف | G1: شماره | H1: ترمیم /تعویض | I1: تعویضی | J1: مرمتی | K1: ارسال به واحد مرمت | L1: سنگ مرمتی آماده | M1: نصب مرمتی شده | N1: ارسال به واحد تعویض | O1: سنگ تعویضی آماده | P1: تعویضی نصب شده | Q1: توضیحات
B2: 1 | C2: *** | D2: شهید گمنام | E2: 28 | F2: 6 | G2: 1 | H2: تعویض | I2: 1 | N2: 1
B3: 2 | C3: عباس | D3: انزلی | E3: 28 | F3: 2 | G3: 10 | H3: ترمیمی | I3: 0 | J3: 1 | M3: 1 | N3: 0
B4: 3 | C4: *** | D4: شهید گمنام | E4: 28 | F4: 12 | G4: 10 | H4: ترمیمی | J4: 1 | M4: 1
B5: 4 | C5: حسین | D5: شیری | E5: 28 | F5: 18 | G5: 10 | H5: ترمیمی | J5: 1 | Q5: مرمر
B6: 5 | C6: محمدصمد | D6: کاشانی | E6: 28 | F6: 23 | G6: 10 | H6: ترمیمی | J6: 1 | Q6: توسط برادر خزایی رسیدگی شود
B7: 6 | C7: قاسم الله | D7: وردی خانی | E7: 28 | F7: 23 | G7: 9 | H7: ترمیمی | J7: 1 | Q7: مرمر
B8: 7 | C8: *** | D8: شهید گمنام | E8: 28 | F8: 13 | G8: 9 | H8: تعویض | I8: 1 | N8: 0 | P8: 1
B9: 8 | C9: مهدی | D9: مکارچیان | E9: 28 | F9: 9 | G9: 8 | H9: ترمیمی | J9: 1 | Q9: مرمر
B10: 9 | C10: مصطفی | D10: بلاقت نیا | E10: 28 | F10: 33 | G10: 8 | H10: ترمیمی | J10: 1 | M10: 1
B11: 10 | C11: هوشنگ | D11: زارعی | E11: 28 | F11: 35 | G11: 7 | H11: ترمیمی | J11: 1
B12: 11 | C12: مصطفی | D12: غلامی | E12: 28 | F12: 24 | G12: 7 | H12: ترمیمی | J12: 1 | Q12: مرمر
B13: 12 | C13: محمود | D13: حاج اکبری | E13: 28 | F13: 23 | G13: 7 | H13: ترمیمی | J13: 1 | Q13: مرمر
B14: 13 | C14: ولی الله | D14: رضائی | E14: 28 | F14: 32 | G14: 5 | H14: ترمیمی | J14: 1 | Q14: مرمر
B15: 14 | C15: حسن | D15: رضائی | E15: 28 | F15: 18 | G15: 4 | H15: تعویض | I15: 1 | N15: 1 | Q15: توسط برادر خزایی رسیدگی شود
B16: 15 | C16: حفیظ الله | D16: ترابی | E16: 28 | H16: تعویض | I16: 1 | N16: 1
B17: 16 | C17: حسین | D17: محمدی | E17: 28 | F17: 17 | G17: 4 | H17: ترمیمی | J17: 1 | M17: 1
B18: 17 | C18: علی رضا | D18: دهقان منشادی | E18: 28 | F18: 18 | G18: 4 | H18: ترمیمی | J18: 1 | Q18: مرمر
B19: 18 | C19: سید ابراهیم | D19: موسوی | E19: 28 | F19: 26 | G19: 4 | H19: ترمیمی | J19: 1 | Q19: مرمر
B20: 19 | C20: مهدی | D20: باقری نصرآبادی | E20: 28 | F20: 28 | G20: 4 | H20: ترمیمی | J20: 1 | M20: 1
B21: 20 | C21: علی | D21: حسینی | E21: 28 | F21: 31 | G21: 4 | H21: ترمیمی | J21: 1 | Q21: مرمر
B22: 21 | C22: حسین | D22: اسماعیلی | E22: 28 | F22: 33 | G22: 4 | H22: ترمیمی | J22: 1
B23: 22 | C23: محمدرضا | D23: میرزائی | E23: 28 | H23: ترمیمی | J23: 1
B24: 23 | C24: محسن | D24: آژوی | E24: 28 | F24: 31 | G24: 3 | H24: ترمیمی | J24: 1
B25: 24 | C25: سیدمجتبی | D25: میرصانع | E25: 28 | F25: 30 | G25: 3 | H25: ترمیمی | I25: 0 | J25: 1 | M25: 1 | N25: 0 | O25: 0
B26: 25 | C26: عبدالصالح | D26: خراسانی | E26: 28 | F26: 11 | G26: 2 | H26: ترمیمی | J26: 1 | M26: 1
B27: 26 | C27: غلامرضا | D27: آقاجانی | E27: 28 | F27: 33 | G27: 2 | H27: ترمیمی | I27: 0 | J27: 1 | M27: 1
B28: 27 | C28: حسین | D28: کیانی | E28: 28 | F28: 29 | G28: 2 | H28: تعویض | I28: 1 | N28: 1
B29: 28 | C29: غلامرضا | D29: کندزی | E29: 28 | F29: 19 | G29: 2 | H29: ترمیمی | J29: 1 | Q29: مرمر
B30: 29 | C30: سیدمهدی | D30: بهرام موسوی | E30: 28 | F30: 8 | G30: 1 | H30: ترمیمی | J30: 1 | M30: 1
B31: 30 | C31: بابک | D31: زارعی | E31: 28 | F31: 27 | G31: 1 | H31: ترمیمی | J31: 1 | Q31: مرمر
B32: 31 | C32: حسین | D32: رجب پور | E32: 28 | F32: 23 | G32: 2 | H32: ترمیمی | J32: 1 | Q32: مرمر
B33: 32 | C33: وحید | D33: شادالویی | E33: 28 | F33: 5 | G33: 1 | H33: ترمیمی | I33: 0 | J33: 1 | M33: 1 | N33: 0
B34: 33 | C34: علیرضا | D34: مقدم سلیمی | E34: 28 | F34: 20 | G34: 1 | H34: ترمیمی | I34: 0 | J34: 1 | M34: 1 | N34: 0
B35: 34 | C35: نیرو | D35: رزاقی | E35: 28 | F35: 21 | G35: 1 | H35: ترمیمی | J35: 1
B36: 35 | C36: غلامرضا | D36: ناجی | E36: 28 | F36: 11 | G36: 1 | H36: ترمیمی | I36: 0 | J36: 1 | M36: 1 | N36: 0
B37: 36 | C37: حسن | D37: ابراهیمی | E37: 28 | F37: 16 | G37: 4 | H37: ترمیمی | J37: 1 | M37: 1
B38: 37 | C38: بهرام | D38: خدایی | E38: 28 | F38: 28 | G38: 7 | H38: ترمیمی | J38: 1 | M38: 1 | Q38: توسط برادر خزایی رسیدگی شود
B39: 38 | C39: علی | D39: خان بابائی | E39: 28 | F39: 57 | G39: 3 | H39: ترمیمی | J39: 1
B40: 39 | C40: امیر | D40: نانگیر | E40: 28 | F40: 51 | G40: 2 | H40: ترمیمی | J40: 1
...

Sheet قطعه 29
C1: نام | D1: نام خانوادگی | E1: قطعه | F1: ردیف | G1: شماره | H1: ترمیم /تعویض | I1: تعویضی | J1: مرمتی | K1: ارسال به واحد مرمت | L1: سنگ مرمتی آماده | M1: نصب مرمتی شده | N1: ارسال به واحد تعویض | O1: سنگ تعویضی آماده | P1: تعویضی نصب شده | Q1: توضیحات
B2: 1 | C2: مهدی | D2: وکیلی | E2: 29 | F2: 41 | G2: 3 | H2: ترمیمی | J2: 1 | M2: 1
B3: 2 | C3: عباس | D3: خظابی | E3: 29 | F3: 4 | G3: 4 | H3: ترمیمی | J3: 1 | M3: 1
B4: 3 | C4: سلمان | D4: عباسقلی پور | E4: 29 | F4: 42 | G4: 3 | H4: ترمیمی | J4: 1 | M4: 1
B5: 4 | C5: علیرضا | D5: مقصودی | E5: 29 | F5: 5 | G5: 5 | H5: ترمیمی | J5: 1 | M5: 1
B6: 5 | C6: مسعود | D6: شیخ بابایی | E6: 29 | F6: 16 | G6: 3 | H6: ترمیمی | J6: 1 | M6: 1
B7: 6 | C7: فرهنگ | D7: طاهری نیا | E7: 29 | F7: 17 | G7: 4 | H7: ترمیمی | J7: 1 | M7: 1
B8: 7 | C8: مصطفی | D8: آقاجانی | E8: 29 | F8: 11 | G8: 3 | H8: ترمیمی | J8: 1 | M8: 1
B9: 8 | C9: بهرام | D9: بینایی مقدم | E9: 29 | F9: 7 | G9: 3 | H9: ترمیمی | J9: 1
B10: 9 | C10: محمد | D10: اسحقی | E10: 29 | F10: 20 | G10: 4 | H10: ترمیمی | J10: 1 | M10: 1 | P10: 1
B11: 10 | C11: عارف | D11: محمدتقی رجبی | E11: 29 | F11: 45 | G11: 1 | H11: تعویضی | I11: 1 | Q11: علوی
B12: 11 | C12: عباس | D12: صحرایی | E12: 29 | F12: 1 | G12: 6 | H12: ترمیمی | J12: 1 | M12: 1
B13: 12 | C13: سعید | D13: وقایعی | E13: 29 | F13: 23 | G13: 6 | H13: ترمیمی | J13: 1 | Q13: ترمیم شود در صورت نیاز تعویض شود.
B14: 13 | C14: عباسعلی | D14: ابراهیم آبادی | E14: 29 | F14: 18 | G14: 6 | H14: ترمیمی | J14: 1 | M14: 1
B15: 14 | C15: جلال | D15: میربیگی | E15: 29 | F15: 12 | G15: 6 | H15: ترمیمی | J15: 1 | M15: 1
B16: 15 | C16: غلامعلی | D16: اسد بروجردی | E16: 29 | F16: 17 | G16: 6 | H16: ترمیمی | J16: 1 | M16: 1
B17: 16 | C17: شکرالله | D17: محسنی | E17: 29 | F17: 15 | G17: 6 | H17: ترمیمی | J17: 1 | M17: 1
B18: 17 | C18: مسعود | D18: حکیم الهی | E18: 29 | F18: 19 | G18: 5 | H18: ترمیمی | J18: 1 | M18: 1
B19: 18 | C19: ولی الله | D19: عباسی | E19: 29 | F19: 21 | G19: 5 | H19: ترمیمی | J19: 1 | M19: 1
B20: 19 | C20: محمدرضا | D20: الیکایی آهاری | E20: 29 | F20: 15 | G20: 5 | H20: ترمیمی | J20: 1 | M20: 1
B21: 20 | C21: اصغر | D21: قرایی | E21: 29 | F21: 31 | G21: 2 | H21: ترمیمی | J21: 1 | M21: 1
B22: 21 | C22: علیرضا | D22: برجعلی خانی | E22: 29 | F22: 17 | G22: 5 | H22: ترمیمی | J22: 1 | M22: 1
B23: 22 | C23: مصطفی | D23: روشنایی | E23: 29 | F23: 8 | G23: 4 | H23: ترمیمی | J23: 1 | M23: 1
B24: 23 | C24: امیر | D24: جلوداری | E24: 29 | F24: 52 | G24: 3 | H24: ترمیمی | J24: 1 | M24: 1
B25: 24 | C25: محمود | D25: زمانی | E25: 29 | F25: 26 | G25: 3 | H25: ترمیمی | J25: 1 | M25: 1
... B32: 31 | C32: غلامرضا | D32: حدادی | E32: 29 | F32: 11 | G32: 5 | H32: ترمیمی | J32: 1 | M32: 1
B33: 32 | C33: مجید | D33: مداح | E33: 29 | F33: 47 | G33: 3 | H33: تعویضی | I33: 1
B34: 33 | C34: محمدرضا | D34: عطارباش | E34: 29 | F34: 5 | G34: 3 | H34: ترمیمی | J34: 1 | M34: 1
B35: 34 | C35: ابراهیم | D35: نوری | E35: 29 | F35: 37 | G35: 4 | H35: ترمیمی | J35: 1 | M35: 1
B36: 35 | C36: امیر | D36: سنجرنیشابوری | E36: 29 | F36: 3 | G36: 3 | H36: ترمیمی | J36: 1 | M36: 1
B37: 36 | C37: رضا | D37: علی محمدی | E37: 29 | F37: 18 | G37: 5 | H37: ترمیمی | J37: 1 | M37: 1
B38: 37 | C38: احمد | D38: زند کریم خانی | E38: 29 | F38: 5 | G38: 5 | H38: تعویضی | I38: 1 | P38: 1 | Q38: سنگ ساخته شده و در عکس زنی می باشد.
B39: 38 | C39: محمد تقی | D39: رحمانی | E39: 29 | F39: 35 | G39: 1 | H39: تعویضی | I39: 1 | P39: 1
B40: 39 | C40: رضا | D40: کشور دوست | E40: 29 | F40: 1 | G40: 2 | H40: تعویضی | I40: 1 | P40: 1
B41: 40 | C41: امیر عباس | D41: جعفرزاده | E41: 29 | F41: 9 | G41: 2 | H41: تعویضی | I41: 1 | P41: 1
B42: 41 | C42: کاظم | D42: فولادی | E42: 29 | F42: 20 | G42: 2 | H42: تعویضی | I42: 1 | P42: 1
B43: 42 | C43: حسین | D43: میرزائی نیا | E43: 29 | F43: 43 | G43: 3 | H43: تعویضی | I43: 1 | P43: 1
B44: 43 | C44: مجتبی | D44: سرنامی | E44: 29 | F44: 46 | G44: 3 | H44: تعویضی | I44: 1 | P44: 1
B45: 44 | C45: جمشید | D45: محمدی | E45: 29 | F45: 21 | G45: 4 | H45: تعویضی | I45: 1 | P45: 1
B46: 45 | C46: رضا | D46: شعیبی | E46: 29 | F46: 38 | G46: 4 | H46: تعویضی | I46: 1 | P46: 1
...

Sheet قطعه 40
B1: ردیف | C1: نام | D1: نام خانوادگی | E1: قطعه | F1: ردیف | G1: شماره | H1: ترمیم /تعویض | I1: تعویضی | J1: مرمتی | K1: ارسال به واحد مرمت | L1: سنگ مرمتی آماده | M1: نصب مرمتی شده | N1: ارسال به واحد تعویض | O1: سنگ تعویضی آماده | P1: تعویضی نصب شده | Q1: توضیحات
B2: 1 | C2: موسی | D2: جوادی | E2: 40 | F2: 11 | G2: 10 | H2: ترمیمی | J2: 1 | M2: 1
B3: 2 | C3: محمود | D3: باقری | E3: 40 | F3: 5 | G3: 10 | H3: ترمیمی | J3: 1 | M3: 1
B4: 3 | C4: خسرو | D4: دستگیر سازی منفرد | E4: 40 | F4: 30 | G4: 1 | H4: ترمیمی | J4: 1 | Q4: نشده
B5: 4 | C5: حسن (منصور) | D5: ارباب زاده | E5: 40 | F5: 32 | G5: 3 | H5: ترمیمی | J5: 1 | M5: 1 | Q5: شده
B6: 5 | C6: حمید | D6: کریمی | E6: 40 | F6: 32 | G6: 5 | H6: ترمیمی | J6: 1 | M6: 1
B7: 6 | C7: محمدباقر(علی) | D7: یزدی | E7: 40 | F7: 26 | G7: 4 | H7: تعویضی | I7: 1 | P7: 1
B8: 7 | C8: محب علی | D8: نباتی | E8: 40 | H8: تعویضی | I8: 1 | P8: 1
B9: 8 | C9: رضا | D9: جعفری | E9: 40 | F9: 75 | G9: 20 | H9: ترمیمی | J9: 1 | Q9: نشده
B10: 9 | C10: مجتبی | D10: میرزائی | E10: 40 | F10: 23 | G10: 10 | H10: ترمیمی | J10: 1 | M10: 1
B11: 10 | C11: حسین | D11: دهرویه | E11: 40 | F11: 48 | G11: 12 | H11: تعویضی | I11: 1 | Q11: نشده
B12: 11 | C12: مصطفی | D12: هاشمی | E12: 40 | F12: 51 | G12: 12 | H12: ترمیمی | J12: 1 | Q12: نشده
B13: 12 | C13: محمود | D13: نصیری اسفندآبادی | E13: 40 | F13: 48 | G13: 11 | H13: تعویضی | I13: 1 | P13: 1 | Q13: انجام شد
B14: 13 | C14: علیرضا | D14: سرهنگ خانلری | E14: 40 | F14: 40 | G14: 11 | H14: تعویضی | I14: 1 | P14: 1 | Q14: انجام شد
B15: 14 | C15: محی الدین | D15: خانی فرسنگی | E15: 40 | F15: 38 | G15: 10 | H15: تعویضی | I15: 1 | P15: 1 | Q15: انجام شد
B16: 15 | C16: حمید | D16: محمد بیگی | E16: 40 | F16: 87 | G16: 11 | H16: تعویضی | I16: 1 | P16: 1
B17: 16 | C17: مرتضی | D17: براتی | E17: 40 | F17: 97 | G17: 12 | H17: تعویضی | I17: 1 | P17: 1
B18: 17 | C18: سید سعید | D18: سید فرشچیان | E18: 40 | F18: 43 | G18: 11 | H18: تعویضی | I18: 1
B19: 18 | C19: ناصر | D19: چابکی | E19: 40 | F19: 46 | G19: 10 | H19: ترمیمی | J19: 1 | M19: 1
B20: 19 | C20: عادل | D20: سلجوقی | E20: 40 | F20: 44 | G20: 7 | H20: ترمیمی | J20: 1 | Q20: نیازی ندارد
B21: 20 | C21: مالک | D21: ابریشم | E21: 40 | F21: 49 | G21: 5 | H21: ترمیمی | J21: 1 | Q21: نیازی ندارد
B22: 21 | C22: احمد | D22: قاسمی نژاد کرمانی | E22: 40 | F22: 50 | G22: 5 | H22: ترمیمی | J22: 1 | M22: 1 | Q22: کتیبه شهید نیز ترمیم شد
B23: 22 | C23: حمیدرضا | D23: طاهر حکاک | E23: 40 | F23: 51 | G23: 4 | H23: ترمیمی | J23: 1 | M23: 1
B24: 23 | C24: مجید | D24: قلی پور | E24: 40 | F24: 22 | G24: 4 | H24: ترمیمی | J24: 1 | Q24: نشده
B25: 24 | C25: حسن | D25: خلج | E25: 40 | F25: 48 | H25: تعویضی | I25: 1 | N25: 1 | Q25: سنگ جدید عینا مطابق قبلی ساخته شود
B26: 25 | C26: محمد رضا | D26: حیدر نژاد | E26: 40 | F26: 47 | G26: 3 | H26: ترمیمی | J26: 1 | Q26: نشده
B27: 26 | C27: محمد | D27: اروجعلی زاده | E27: 40 | F27: 49 | G27: 1 | H27: ترمیمی | J27: 1 | M27: 1
B28: 27 | C28: فرامرز | D28: حسنی علیایی | E28: 40 | F28: 65 | G28: 1 | H28: ترمیمی | J28: 1 | Q28: نشده
B29: 28 | C29: صمد | D29: نجفی | E29: 40 | F29: 64 | G29: 1 | H29: تعویضی | I29: 1 | P29: 1
B30: 29 | C30: یوسف | D30: متقی اصل | E30: 40 | F30: 66 | G30: 2 | H30: ترمیمی | J30: 1 | Q30: نشده
B31: 30 | C31: ناصر | D31: بهرامی | E31: 40 | F31: 43 | G31: 2 | H31: ترمیمی | J31: 1 | Q31: نشده
B32: 31 | C32: بیوک | D32: خندان | E32: 40 | F32: 62 | G32: 2 | H32: تعویضی | I32: 1 | O32: 1 | Q32: نصب نشده است به علت چاپ تصویر روی سنگ
B33: 32 | C33: علی | D33: شریفی نژاد | E33: 40 | F33: 58 | G33: 1 | H33: تعویضی | I33: 1 | P33: 1
B34: 33 | C34: محرم علی | D34: جعفری | E34: 40 | F34: 133 | G34: 2 | H34: تعویضی | I34: 1 | Q34: سنگ خاص بوده از مدیر بهسازی پیگیری شود
B35: 34 | C35: وحید | D35: فرخ نظر | E35: 40 | F35: 120 | G35: 6 | H35: تعویضی | I35: 1
B36: 35 | C36: احمد | D36: پور بقائی لنگرودی | E36: 40 | F36: 57 | G36: 2 | H36: تعویضی | I36: 1 | P36: 1
B37: 36 | C37: شهرام | D37: شهید ثالت | E37: 40 | F37: 53 | G37: 2 | H37: تعویضی | I37: 1 | Q37: نشده
B38: 37 | C38: حسن | D38: زارع طوافی | E38: 40 | F38: 53 | G38: 3 | H38: ترمیمی | J38: 1 | M38: 1
B39: 38 | C39: ابراهیم | D39: کرد | E39: 40 | F39: 55 | G39: 4 | H39: تعویضی | I39: 1
B40: 39 | C40: رضا | D40: همتی | E40: 40 | F40: 57 | G40: 4 | H40: تعویضی | I40: 1
...

Sheet قطعه 53
B1: ردیف | C1: نام | D1: نام خانوادگی | E1: قطعه | F1: ردیف | G1: شماره | H1: ترمیم /تعویض | I1: تعویضی | J1: مرمتی | K1: ارسال به واحد مرمت | L1: سنگ مرمتی آماده | M1: نصب مرمتی شده | N1: ارسال به واحد تعویض | O1: سنگ تعویضی آماده | P1: تعویضی نصب شده | Q1: توضیحات
B2: 1 | C2: مرتضی | D2: سازمند | E2: 53 | F2: 153 | G2: 1 | H2: تعویضی | I2: 1 | P2: 1 | Q2: انجام شد
B3: 2 | C3: احمد | D3: غلام نژاد | E3: 53 | F3: 156 | G3: 2 | H3: تعویضی | I3: 1 | P3: 1 | Q3: انجام شد
B4: 3 | C4: عباس | D4: صفاریان نژاد | E4: 53 | F4: 172 | G4: 2 | H4: تعویضی | I4: 1 | P4: 1 | Q4: انجام شد
B5: 4 | C5: مصطفی | D5: رضائی اعلم | E5: 53 | F5: 176 | G5: 2 | H5: ترمیمی | J5: 1
B6: 5 | C6: بهروز | D6: آقا علی اکبری | E6: 53 | F6: 178 | G6: 2 | H6: تعویضی | I6: 1 | P6: 1 | Q6: انجام شد
B7: 6 | C7: طاهر | D7: نوبخت قره شیران | E7: 53 | F7: 158 | G7: 4 | H7: تعویضی | I7: 1 | P7: 1
B8: 7 | C8: محمدرضا | D8: سیفی | E8: 53 | F8: 165 | G8: 4 | H8: تعویضی | I8: 1 | P8: 1
B9: 8 | C9: حسین | D9: قلیچی | E9: 53 | F9: 59 | G9: 5 | H9: تعویضی | I9: 1 | P9: 1
B10: 9 | C10: اسرافیل | D10: آذرپندار | E10: 53 | F10: 168 | G10: 4 | H10: تعویضی | I10: 1 | P10: 1
B11: 10 | C11: مسعود | D11: عظیمی | E11: 53 | F11: 73 | G11: 4 | H11: تعویضی | I11: 1 | P11: 1
B12: 11 | C12: نظام الدین | D12: مرانکی | E12: 53 | F12: 172 | G12: 4 | H12: تعویضی | I12: 1 | P12: 1
B13: 12 | C13: محمدرضا | D13: رضوی خالقی | E13: 53 | F13: 180 | G13: 4 | H13: تعویضی | I13: 1 | P13: 1
B14: 13 | C14: حسین | D14: رضاخان | E14: 53 | F14: 164 | G14: 5 | H14: تعویضی | I14: 1 | P14: 1
B15: 14 | C15: قیس | D15: دانا | E15: 53 | F15: 157 | G15: 5 | H15: تعویضی | I15: 1 | P15: 1
B16: 15 | C16: محمد | D16: طاهری | E16: 53 | F16: 155 | G16: 6 | H16: تعویضی | I16: 1 | P16: 1
B17: 16 | C17: مجید | D17: میرزائی | E17: 53 | F17: 177 | G17: 7 | H17: تعویضی | I17: 1 | P17: 1 | Q17: انجام شد
B18: 17 | C18: رجبعلی | D18: بکشلو | E18: 53 | F18: 154 | G18: 8 | H18: تعویضی | I18: 1 | P18: 1 | Q18: انجام شد
B19: 18 | C19: محمد | D19: فروغی | E19: 53 | F19: 170 | G19: 8 | H19: تعویضی | I19: 1 | P19: 1
B20: 19 | C20: سعید | D20: کاووس همایونی | E20: 53 | F20: 175 | G20: 9 | H20: تعویضی | I20: 1 | P20: 1 | Q20: انجام شد
B21: 20 | C21: محمد | D21: یدرنجی اقدم | E21: 53 | F21: 153 | G21: 9 | H21: تعویضی | I21: 1 | P21: 1 | Q21: انجام شد
B22: 21 | C22: ابوالفضل | D22: فتحیان | E22: 53 | F22: 152 | G22: 10 | H22: تعویضی | I22: 1 | P22: 1
B23: 22 | C23: شعبان | D23: فرجی | E23: 53 | F23: 166 | G23: 11 | H23: تعویضی | I23: 1 | P23: 1 | Q23: انجام شد
B24: 23 | C24: یوسف | D24: ضیائی | E24: 53 | F24: 156 | G24: 11 | H24: تعویضی | I24: 1 | P24: 1 | Q24: انجام شد
B25: 24 | C25: ابوالفضل | D25: حاجی بیگی | E25: 53 | F25: 155 | G25: 11 | H25: تعویضی | I25: 1 | P25: 1
B26: 25 | C26: قدرت الله | D26: متین راسخ | E26: 53 | F26: 163 | G26: 12 | H26: تعویضی | I26: 1 | P26: 1 | Q26: انجام شد
B27: 26 | C27: الله وردی | D27: عالی نژاد | E27: 53 | F27: 167 | G27: 12 | H27: تعویضی | I27: 1 | P27: 1
B28: 27 | C28: رمضانعلی | D28: نوده فراهانی | E28: 53 | F28: 156 | G28: 13 | H28: تعویضی | I28: 1 | P28: 1
B29: 28 | C29: فرزاد | D29: توکلی | E29: 53 | F29: 155 | G29: 13 | H29: تعویضی | I29: 1 | P29: 1
B30: 29 | C30: نظرعلی | D30: میرآخوری | E30: 53 | F30: 168 | G30: 14 | H30: تعویضی | I30: 1 | P30: 1 | Q30: انجام شد
B31: 30 | C31: مهدی | D31: حاج محمد جعفر تهرانی | E31: 53 | F31: 179 | G31: 3 | H31: تعویضی | I31: 1 | J31: 0 | P31: 1
B32: 31 | C32: احمد | D32: حق لسان | E32: 53 | F32: 172 | G32: 3 | H32: ترمیمی | J32: 1
B33: 32 | C33: یعقوب | D33: منظم رازلیقی | E33: 53 | F33: 162 | G33: 3 | H33: تعویضی | I33: 1 | P33: 1
B34: 33 | C34: پرویز | D34: سعادتی | E34: 53 | F34: 162 | G34: 4 | H34: تعویضی | I34: 1 | J34: 0 | P34: 1
B35: 34 | C35: سعید | D35: جعفری | E35: 53 | F35: 177 | G35: 4 | H35: ترمیمی | J35: 1
B36: 35 | C36: محمدرضا | D36: ترامشلو | E36: 53 | F36: 180 | G36: 5 | H36: تعویضی | I36: 1 | P36: 1
B37: 36 | C37: حسن | D37: شکوهی تبریزی | E37: 53 | F37: 179 | G37: 5 | H37: تعویضی | I37: 1 | P37: 1
B38: 37 | C38: قاسم | D38: حیدری | E38: 53 | F38: 175 | G38: 5 | H38: تعویضی | I38: 1 | P38: 1
B39: 38 | C39: عباس | D39: چراغی | E39: 53 | F39: 172 | G39: 5 | H39: تعویضی | I39: 1 | P39: 1 | Q39: عدم نصب
B40: 39 | C40: رضا | D40: قدیانی | E40: 53 | F40: 170 | G40: 5 | H40: تعویضی | I40: 1 | P40: 1
...

Sheet عکس دار
B1: ردیف | C1: نام | D1: نام خانوادگی | E1: نام پدر | F1: قطعه | G1: ردیف | H1: شماره | I1: عکس | J1: ارسال به واحد سنگ | K1: چاپ | L1: نصب | M1: توضیحات
B2: 1 | C2: محمود | D2: محسنی سربندی | I2: * | J2: * | K2: *
B3: 2 | C3: رحیم | D3: مختار تجویدی | I3: * | J3: * | K3: *
B4: 3 | C4: سید مهدی | D4: سجادی | I4: * | J4: * | K4: *
B5: 4 | C5: حسین | D5: ترانه | I5: * | J5: * | K5: *
B6: 5 | C6: حسین | D6: مشایخی | I6: * | J6: * | K6: *
B7: 6 | C7: اصغر | D7: صادقی | I7: * | J7: * | K7: *
B8: 7 | C8: حسن | D8: عظیمی | I8: * | J8: * | K8: *
B9: 8 | C9: جواد | D9: سلیمانی | I9: * | J9: * | K9: *
B10: 9 | C10: مهدی | D10: حاجی محمودزاده ممقانی | I10: * | J10: * | K10: *
B11: 10 | C11: اصغر | D11: وایگانی | I11: * | J11: * | K11: *
B12: 11 | C12: داود | D12: غلامی ابقاء | I12: * | J12: * | K12: *
B13: 12 | C13: علی | D13: مرادی | I13: * | J13: * | K13: *
... B18: 17 | C18: محمدمهدی | D18: مطهری خوانساری | I18: * | J18: * | K18: *
B19: 18 | C19: جابر | D19: نجفی مقدم | E19: خداشکر | F19: 29 | G19: 45 | H19: 8 | I19: * | J19: * | K19: *
B20: 19 | C20: غلامرضا | D20: مالکی | I20: * | J20: * | K20: *
B21: 20 | C21: علیرضا | D21: بادفر | I21: * | J21: * | K21: *
B22: 21 | C22: زین العابدین | D22: قمی | I22: * | J22: * | K22: *
B23: 22 | C23: منصور | D23: ورزدار | I23: * | J23: * | K23: *
B24: 23 | C24: جلال | D24: جعفری قشلاق چایی | I24: * | J24: * | K24: *
B25: 24 | C25: سید حسن (امیر) | D25: سید مومنی | E25: سید طاهر | F25: 26 | G25: 53 | H25: 15 | I25: * | J25: * | K25: *
B26: 25 | C26: علی | D26: شهیدزاده | I26: * | J26: * | K26: *
B27: 26 | C27: بهنام | D27: عیسی زاده | I27: * | J27: * | K27: *
B28: 27 | C28: علی | D28: قنبری | I28: * | J28: * | K28: *
B29: 28 | C29: اصغر | D29: مختاری | I29: * | J29: * | K29: *
B30: 29 | C30: محمد | D30: یا سعید زند کریم خانی | E30: هاشم
B31: 30 | C31: حسین | D31: تسبندی | I31: * | J31: * | K31: *
B32: 31 | C32: مجتبی | D32: داودی | I32: * | J32: * | K32: *
B33: 32 | C33: محمدباقر | D33: نجات ثابت | I33: * | J33: * | K33: *
B34: 33 | C34: یعقوب | D34: معظم رازلیقی | I34: * | J34: * | K34: *
B35: 34 | C35: محمد | D35: اکبری نژاد | I35: * | J35: * | K35: *
B36: 35 | C36: ابوالقاسم | D36: امیراحمدی | I36: * | J36: * | K36: *
B37: 36 | C37: علی محمد | D37: جوادی اصل | I37: * | J37: * | K37: *
B38: 37 | C38: محمدرضا | D38: کشفی اصل | I38: * | J38: * | K38: *
B39: 38 | C39: مصطفی | D39: درزی | I39: * | J39: * | K39: *
B40: 39 | C40: سید حسن | D40: رضوی طالمی | I40: * | J40: * | K40: *
B41: 40 | C41: احمد | D41: کشاورز صیفئی
B42: 41 | C42: احمد | D42: عبدالعلیان | I42: * | J42: * | K42: *
B43: 42 | C43: حسن | D43: یگانه | E43: غلام رضا | F43: 53 | K43: *
B44: 43 | C44: محمود | D44: علیان نژاد | I44: * | J44: * | K44: *
...

Sheet آمار
B2: آمار | C2: کل سنگ قطعه | D2: آمار تعویض سنگ‌ها | G2: آمار ترمیم سنگ‌ها | J2: درصد آسیب دیدگی به نسبت کل قطعه | K2: جمع کل آسیب دیدها
B3: قطعه | C3: تعداد | D3: قابل تعویض | E3: تعویض شده | F3: باقی مانده | G3: قابل ترمیم | H3: ترمیم شده | I3: باقی مانده | J3: درصدآسیب قطعه | K3: کل قابل تعویض و ترمیم | L3: کل تعویض و ترمیم شده | M3: کل باقی مانده
B4: 24 | C4: 6100 | D4: 281 | E4: ='قطعه 24'!P599 -> 166 | F4: =D4-E4 -> 115 | G4: ='قطعه 24'!J599 -> 316 | H4: ='قطعه 24'!M599 -> 120 | I4: =G4-H4 -> 196 | J4: =K4/C4 -> 0.097868852 | K4: =D4+G4 -> 597 | L4: =E4+H4 -> 286 | M4: =F4+I4 -> 311
B5: 26 | C5: 4514 | D5: 170 | E5: ='قطعه 26'!P367 -> 158 | F5: =D5-E5 -> 12 | G5: ='قطعه 26'!J367 -> 143 | H5: ='قطعه 26'!M367 -> 132 | I5: =G5-H5 -> 11 | J5: =K5/C5 -> 0.069339832 | K5: =D5+G5 -> 313 | L5: =E5+H5 -> 290 | M5: =F5+I5 -> 23
B6: 27 | C6: 3177 | D6: ='قطعه 27'!I325 -> 280 | E6: ='قطعه 27'!P325 -> 235 | F6: =D6-E6 -> 45 | G6: ='قطعه 27'!J325 -> 43 | H6: =SUM('قطعه 27'!M325) -> 1 | I6: =G6-H6 -> 42 | J6: =K6/C6 -> 0.10166824 | K6: =D6+G6 -> 323 | L6: =E6+H6 -> 236 | M6: =F6+I6 -> 87
B7: 28 | C7: 3523 | D7: ='قطعه 28'!I515 -> 286 | E7: ='قطعه 28'!P515 -> 230 | F7: =D7-E7 -> 56 | G7: ='قطعه 28'!J515 -> 203 | H7: =SUM('قطعه 28'!M515) -> 135 | I7: =G7-H7 -> 68 | J7: =K7/C7 -> 0.13880216 | K7: =D7+G7 -> 489 | L7: =E7+H7 -> 365 | M7: =F7+I7 -> 124
B8: 29 | C8: 2743 | D8: ='قطعه 29'!I417 -> 226 | E8: ='قطعه 29'!P417 -> 174 | F8: =D8-E8 -> 52 | G8: ='قطعه 29'!J417 -> 188 | H8: =SUM('قطعه 29'!M417) -> 184 | I8: =G8-H8 -> 4 | J8: =K8/C8 -> 0.15092964 | K8: =D8+G8 -> 414 | L8: =E8+H8 -> 358 | M8: =F8+I8 -> 56
B9: 40 | C9: 2948 | D9: ='قطعه 40'!I210 -> 133 | E9: ='قطعه 40'!P210 -> 81 | F9: =D9-E9 -> 52 | G9: ='قطعه 40'!J210 -> 75 | H9: ='قطعه 40'!M210 -> 30 | I9: =G9-H9 -> 45 | J9: =K9/C9 -> 0.070556309 | K9: =D9+G9 -> 208 | L9: =E9+H9 -> 111 | M9: =F9+I9 -> 97
B10: 53 | C10: 3092 | D10: ='قطعه 53'!I555 -> 359 | E10: ='قطعه 53'!P555 -> 342 | F10: =D10-E10 -> 17 | G10: ='قطعه 53'!J555 -> 193 | H10: 7 | I10: =G10-H10 -> 186 | J10: =K10/C10 -> 0.17852523 | K10: =D10+G10 -> 552 | L10: =E10+H10 -> 349 | M10: =F10+I10 -> 203
B11: جمع | C11: =SUM(C4:C10) -> 26097 | D11: =SUM(D4:D10) -> 1735 | E11: =SUM(E4:E10) -> 1386 | F11: =SUM(F4:F10) -> 349 | G11: =SUM(G4:G10) -> 1161 | H11: =SUM(H4:H10) -> 609 | I11: =SUM(I4:I10) -> 552 | J11: =K11/C11 -> 0.11097061 | K11: =SUM(K4:K10) -> 2896 | L11: =SUM(L4:L10) -> 1995 | M11: =SUM(M4:M10) -> 901
